Workbook

Sheet Faculty
A1: Full-time - Faculty | C1: Tload | D1: Other | E1: OverLoad | F1: Total
A2: 1 | B2: Panfilo A. Actub, Jr. | C2: ='Actub P'!L22 -> 9 | D2: ='Actub P'!L27 -> 12 | E2: ='Actub P'!L45 -> 11 | F2: =SUM(C2:E2) -> 32
A3: 2 | B3: Gabriel E Casino, | C3: 0 | D3: ='Casiño G'!L26 -> 21 | E3: ='Casiño G'!L42 -> 12 | F3: =SUM(C3:E3) -> 33
A4: 3 | B4: Kent Russell N Casino, | C4: =CasiñoK!L22 -> 9 | D4: =CasiñoK!L27 -> 12 | E4: =CasiñoK!L45 -> 9 | F4: =SUM(C4:E4) -> 30
A5: 4 | B5: Afuljie Caturan, | C5: ='Caturan A'!L27 -> 21 | D5: ='Caturan A'!L32 -> 0 | E5: ='Caturan A'!L49 -> 7 | F5: =SUM(C5:E5) -> 28
A6: 5 | B6: Jefrey Delrosario, | C6: ='DelRosario J'!L27 -> 21 | D6: ='DelRosario J'!L32 -> 0 | E6: ='DelRosario J'!L50 -> 9 | F6: =SUM(C6:E6) -> 30
A7: 6 | B7: Ma Geleen O Eduave, | C7: ='Eduave G'!L20 -> 6 | D7: ='Eduave G'!L25 -> 15 | E7: ='Eduave G'!L41 -> 12 | F7: =SUM(C7:E7) -> 33
A8: 7 | B8: Arnel S Llemit, | C8: ='Llemit A'!L22 -> 6 | D8: ='Llemit A'!L27 -> 15 | E8: ='Llemit A'!L46 -> 12 | F8: =SUM(C8:E8) -> 33
A9: 8 | B9: Aldrin T Molawan, | C9: ='Molawan A'!L27 -> 21 | D9: ='Molawan A'!L32 -> 0 | E9: ='Molawan A'!L51 -> 10 | F9: =SUM(C9:E9) -> 31
A10: 9 | B10: Azmie A Oyok, | C10: ='Oyok A'!L22 -> 9 | D10: ='Oyok A'!L27 -> 12 | E10: ='Oyok A'!L48 -> 0 | F10: =SUM(C10:E10) -> 21
A11: 10 | B11: Jan James M Pada, | C11: ='Pada J'!L28 -> 21 | D11: ='Pada J'!L33 -> 0 | E11: ='Pada J'!L51 -> 11 | F11: =SUM(C11:E11) -> 32
A12: 11 | B12: Joniel E Padilla, | C12: ='Padilla J'!L22 -> 9 | D12: 12 | E12: ='Padilla J'!L45 -> 11 | F12: =SUM(C12:E12) -> 32
A13: 12 | B13: Niko A Perez, | C13: ='Perez N'!L28 -> 21 | D13: ='Perez N'!L33 -> 0 | E13: ='Perez N'!L51 -> 12 | F13: =SUM(C13:E13) -> 33
A14: 13 | B14: Janu Vincent A Razalo, | C14: ='Razalo J'!L27 -> 21 | D14: ='Razalo J'!L31 -> 0 | E14: ='Razalo J'!L51 -> 12 | F14: =SUM(C14:E14) -> 33
A15: 14 | B15: Neptale S Roa, | C15: ='Roa N'!L28 -> 21 | D15: ='Roa N'!L33 -> 0 | E15: ='Roa N'!L51 -> 12 | F15: =SUM(C15:E15) -> 33
A16: 15 | B16: Jasmin A Tabada, | C16: ='Tabada J'!L25 -> 21 | D16: ='Tabada J'!L30 -> 0 | E16: ='Tabada J'!L47 -> 9 | F16: =SUM(C16:E16) -> 30
A17: 16 | B17: Kay Rejoice C Waga, | C17: ='Waga KR'!L24 -> 15 | D17: ='Waga KR'!L29 -> 6 | E17: ='Waga KR'!L47 -> 12 | F17: =SUM(C17:E17) -> 33
A19: Part-time - Faculty | C19: Tload | D19: Other | E19: OverLoad | F19: Total
A20: 1 | B20: Eldefonso C Lagulay, | C20: 9 | E20: 6 | F20: =SUM(C20:E20) -> 15
A21: 2 | B21: Marlo Romero, | C21: 10 | E21: 5 | F21: 5
A22: 3 | B22: Mary Ann Ubalde, | C22: 8

Sheet Casiño G
A1: TCC-ADMN-Form 001
A2: TAGOLOAN COMMUNITY COLLEGE
A3: Baluarte, Tagoloan Misamis Oriental
A4: (08822)750-835
A5: Member: Association of Local Colleges & Universities (ALCU)
A6: Individual Faculty Load Sheet
A7: 1st Term Academic Year 2023 - 2024
A9: Surname: Casiño Given Name: Gabriel MI: E
A10: Employment Status: (Put X)
C11: Regular | J11: Contractual
C13: Probationary | J13: Part-Time
A14: TEACHING LOAD
A15: A. Basic Load/Built-In
A16: Subj Code | B16: Descriptive Title | D16: Day | E16: Time | F16: Room | G16: Section | H16: No. of Students | I16: Units | J16: Units | K16: Total | L16: Total
I17: (lec) | J17: (lab) | K17: Units | L17: Hours
E19: TOTAL NUMBER OF UNITS/HRS (BASIC) : | K19: =SUM(K24:K24) -> 0 | L19: 3
A21: B. Other Academic-Related Functions
A22: Subj Code | B22: Descriptive Title | D22: Day | E22: Time | H22: No. of Students | I22: Units | J22: Units | K22: Total | L22: Total
I23: (lec) | J23: (lab) | K23: Units | L23: Hours
A24: College Dean | D24: - | E24: - | F24: - | G24: - | H24: - | I24: - | J24: - | K24: - | L24: 12
A25: IT Administrator | D25: - | E25: - | F25: - | G25: - | H25: - | I25: - | J25: - | K25: - | L25: 9
D26: TOTAL NUMBER OF UNITS/HRS (OTHER FUNCTIONS): | K26: =SUM(K25) -> 0 | L26: =L24+L25 -> 21
A27: C. Consultation Hours
A28: Day | D28: Time | G28: Venue | K28: Number of hrs
A30: Mon | D30: 08:00-05:00PM | G30: IT Office | K30: 8
A31: Fri | D31: 08:00-05:00PM | K31: 8
A32: Wed | D32: 08:00-11:00AM | K32: 3
D33: TOTAL NUMBER OF UNITS/HRS (CONSULTATION): | K33: =SUM(K30:L32) -> 19
D34: SUB-TOTAL (A-C) | K34: =L19+L26+K33 -> 43
A35: D. Overload
A36: Subj Code | B36: Descriptive Title | D36: Day | E36: Time | F36: Room | G36: Section | H36: No. of Students | I36: Units | J36: Units | K36: Total | L36: Total
I37: (lec) | J37: (lab) | K37: Units | L37: Hours
A38: IT 120 | B38: Research1 (Methods of Research in Computing) | D38: Fri | E38: 07:00 AM-10:00 AM | F38: Online | G38: BSIT 3A | H38: 40 | I38: 3 | J38: 0 | K38: 3 | L38: 3
A39: IT 120 | B39: Research1 (Methods of Research in Computing) | D39: Fri | E39: 10:00 AM-01:00 PM | F39: Online | G39: BSIT 3B | H39: 40 | I39: 3 | J39: 0 | K39: 3 | L39: 3
A40: IT 120 | B40: Research1 (Methods of Research in Computing) | D40: Thu | E40: 01:00 PM-04:00 PM | F40: Online | G40: BSIT 3D | H40: 40 | I40: 3 | J40: 0 | K40: 3 | L40: 3
A41: IT 120 | B41: Research1 (Methods of Research in Computing) | D41: Fri | E41: 01:00 PM-04:00 PM | F41: Online | G41: BSIT 3C | H41: 40 | I41: 3 | J41: 0 | K41: 3 | L41: 3
D42: TOTAL NUMBER OF UNITS / HRS (OVERLOAD) | K42: =SUM(K38:K41) -> 12 | L42: =SUM(L38:L41) -> 12
D43: GRAND TOTAL NUMBER OF UNITS/HRS (A-D) | K43: =SUM(K19,K26,K42) -> 12 | L43: =(L19+L26+K33+L42) -> 55
A45: Prepared by: | H45: Noted:
A47: Mr. Gabriel E. Casiño | H47: Ms. Merilyn A.Tangon
...

Sheet CasiñoK
A1: TCC-ADMN-Form 001
A2: TAGOLOAN COMMUNITY COLLEGE
A3: Baluarte, Tagoloan Misamis Oriental
A4: (08822)750-835
A5: Member: Association of Local Colleges & Universities (ALCU)
A6: Individual Faculty Load Sheet
A7: 1st Term Academic Year 2023 - 2024
A9: Surname: Casiño Given Name: Kent Russell MI:
A10: Employment Status: (Put X)
C11: Regular | J11: Contractual
C13: Probationary | J13: Part-Time
A14: TEACHING LOAD
A15: A. Basic Load/Built-In
A16: Subj Code | B16: Descriptive Title | D16: Day | E16: Time | F16: Room | G16: Section | H16: No. of Students | I16: Units | J16: Units | K16: Total | L16: Total
I17: (lec) | J17: (lab) | K17: Units | L17: Hours
A18: IT 131 | B18: Web System and Technologies | D18: Tue | E18: 07:00 AM-10:00 AM | F18: Lab1 | G18: BSIT 4B | H18: 40 | I18: 2 | J18: 1 | K18: 3 | L18: 5
D19: Thu | E19: 09:00 AM-11:00 AM | F19: 20
A20: IT 131 | B20: Web System and Technologies | D20: Wed | E20: 01:00 PM-04:00 PM | F20: Lab1 | G20: BSIT 4C | H20: 40 | I20: 2 | J20: 1 | K20: 3 | L20: 4
D21: Mon | E21: 01:00 PM-03:00 PM | F21: 20
E22: TOTAL NUMBER OF UNITS/HRS (BASIC) : | K22: =SUM(K18:K21) -> 6 | L22: =SUM(L18:L21) -> 9
A23: B. Other Academic-Related Functions
A24: Subj Code | B24: Descriptive Title | D24: Day | E24: Time | H24: No. of Students | I24: Units | J24: Units | K24: Total | L24: Total
I25: (lec) | J25: (lab) | K25: Units | L25: Hours
A26: Computer Programmer | L26: 12
D27: TOTAL NUMBER OF UNITS/HRS (OTHER FUNCTIONS): | K27: =SUM(K26) -> 0 | L27: =SUM(L26) -> 12
A28: C. Consultation Hours
A29: Day | D29: Time | G29: Venue | K29: Number of hrs
A31: Mon | D31: 8AM-1PM | 4PM-6PM | G31: Computer Lab / IT Office | K31: 7
A32: Tue | D32: 8:00-12PM | K32: 4
A33: Wed | D33: 8:00-1PM | K33: 5
A34: Fri | D34: 8:00-11PM | K34: 3
D35: TOTAL NUMBER OF UNITS/HRS (CONSULTATION): | K35: =SUM(K31:L34) -> 19
D36: SUB-TOTAL (A-C) | K36: =L22+L27+K35 -> 40
A37: D. Overload
A38: Subj Code | B38: Descriptive Title | D38: Day | E38: Time | F38: Room | G38: Section | H38: No. of Students | I38: Units | J38: Units | K38: Total | L38: Total
I39: (lec) | J39: (lab) | K39: Units | L39: Hours
A40: IT 131 | B40: Web System and Technologies | D40: Wed | E40: 01:00 PM-04:00 PM | F40: Lab1 | G40: BSIT 4C | H40: 40 | L40: 1
D41: Mon | E41: 01:00 PM-03:00 PM | F41: 20
A42: IT 108 | B42: FUNDAMENTALS OF DATABASE SYSTEM | D42: TTH | E42: 02:30-04:00PM | F42: 22 | G42: BSBA 2E | H42: 40 | I42: 3 | J42: 0 | K42: 3 | L42: 3
A43: IT 131 | B43: Web System and Technologies | D43: Wed | E43: 10:00 AM-01:00 PM | F43: Lab1 | G43: BSIT 4A | H43: 40 | I43: 2 | J43: 1 | K43: 3 | L43: 5
...

Sheet Caturan A
A1: TCC-ADMN-Form 001
A2: TAGOLOAN COMMUNITY COLLEGE
A3: Baluarte, Tagoloan Misamis Oriental
A4: (08822)750-835
A5: Member: Association of Local Colleges & Universities (ALCU)
A6: Individual Faculty Load Sheet
A7: 1st Term Academic Year 2023 - 2024
A9: Surname: Catural Given Name: Alfuljie MI:
A10: Employment Status: (Put X)
C11: Regular | J11: Contractual
C13: Probationary | J13: Part-Time
A14: TEACHING LOAD
A15: A. Basic Load/Built-In
A16: Subj Code | B16: Descriptive Title | D16: Day | E16: Time | F16: Room | G16: Section | H16: No. of Students | I16: Units | J16: Units | K16: Total | L16: Total
I17: (lec) | J17: (lab) | K17: Units | L17: Hours
A18: IT 111 | B18: Social Issues & Professional Issues | D18: Fri | E18: 07:00 AM-10:00 AM | F18: Online | G18: BSIT 2C | H18: 40 | I18: 3 | J18: 0 | K18: 3 | L18: 3
A19: IT 119 | B19: System Integration & Architecture 1 | D19: Tue | E19: 09:00 AM-12:00 PM | F19: Lab2 | G19: BSIT 3D | H19: 40 | I19: 2 | J19: 1 | K19: 3 | L19: 5
D20: Thu | E20: 07:00 AM-09:00 AM | F20: 20
A21: IT 119 | B21: System Integration & Architecture 1 | D21: Thu | E21: 10:00 AM-01:00 PM | F21: Lab2 | G21: BSIT 3B | H21: 40 | I21: 2 | J21: 1 | K21: 3 | L21: 5
D22: Mon | E22: 09:00 AM-11:00 AM | F22: 20
A23: IT 119 | B23: System Integration & Architecture 1 | D23: Tue | E23: 04:00 PM-07:00 PM | F23: Lab2 | G23: BSIT 3A | H23: 40 | I23: 2 | J23: 1 | K23: 3 | L23: 5
D24: Wed | E24: 01:00 PM-03:00 PM | F24: 20
A25: IT 119 | B25: System Integration & Architecture 1 | D25: Thu | E25: 01:00 PM-04:00PM | F25: Lab2 | G25: BSIT 3C | H25: 40 | I25: 2 | J25: 1 | K25: 3 | L25: 3
D26: Mon | E26: 03:00 PM-05:00 PM | F26: 20
E27: TOTAL NUMBER OF UNITS/HRS (BASIC) : | K27: =SUM(K18:K26) -> 15 | L27: =SUM(L18:L26) -> 21
A28: B. Other Academic-Related Functions
A29: Subj Code | B29: Descriptive Title | D29: Day | E29: Time | H29: No. of Students | I29: Units | J29: Units | K29: Total | L29: Total
I30: (lec) | J30: (lab) | K30: Units | L30: Hours
D32: TOTAL NUMBER OF UNITS/HRS (OTHER FUNCTIONS): | K32: =SUM(K31) -> 0 | L32: =SUM(L31) -> 0
A33: C. Consultation Hours
A34: Day | D34: Time | G34: Venue | K34: Number of hrs
A36: Mon | D36: 7AM-9AM | 1PM-3PM | G36: Computer Lab/IT Office | K36: 4
A37: Tue | D37: 7AM-9AM | 1PM-4PM | K37: 5
A38: Wed | D38: 7AM-1PM | K38: 5
A39: Fri | D39: 7AM-12PM | K39: 5
D40: TOTAL NUMBER OF UNITS/HRS (CONSULTATION): | K40: =SUM(K36:L39) -> 19
D41: SUB-TOTAL (A-C) | K41: =L27+L32+K40 -> 40
A42: D. Overload
A43: Subj Code | B43: Descriptive Title | D43: Day | E43: Time | F43: Room | G43: Section | H43: No. of Students | I43: Units | J43: Units | K43: Total | L43: Total
I44: (lec) | J44: (lab) | K44: Units | L44: Hours
...

Sheet Actub P
A1: TCC-ADMN-Form 001
A2: TAGOLOAN COMMUNITY COLLEGE
A3: Baluarte, Tagoloan Misamis Oriental
A4: (08822)750-835
A5: Member: Association of Local Colleges & Universities (ALCU)
A6: Individual Faculty Load Sheet
A7: 1st Term Academic Year 2023 - 2024
A9: Surname: Actub Given Name: Panfilo Jr. MI: A
A10: Employment Status: (Put X)
C11: Regular | J11: Contractual
C13: Probationary | J13: Part-Time
A14: TEACHING LOAD
A15: A. Basic Load/Built-In
A16: Subj Code | B16: Descriptive Title | D16: Day | E16: Time | F16: Room | G16: Section | H16: No. of Students | I16: Units | J16: Units | K16: Total | L16: Total
I17: (lec) | J17: (lab) | K17: Units | L17: Hours
A18: IT 130 | B18: Networking 2 | D18: Mon | E18: 10:00 AM-01:00 PM | F18: Lab1 | G18: BSIT 4A | H18: 40 | I18: 2 | J18: 1 | K18: 3 | L18: 5
D19: Tue | E19: 03:00 PM-05:00 PM | F19: 20
A20: IT 130 | B20: Networking 2 | D20: Thu | E20: 10:00 AM-01:00 PM | F20: Lab1 | G20: BSIT 4B | H20: 40 | I20: 2 | J20: 1 | K20: 3 | L20: 4
D21: Thu | E21: 03:00 PM-05:00 PM | F21: 20
E22: TOTAL NUMBER OF UNITS/HRS (BASIC) : | K22: =SUM(K18:K21) -> 6 | L22: =SUM(L18:L21) -> 9
A23: B. Other Academic-Related Functions
A24: Subj Code | B24: Descriptive Title | D24: Day | E24: Time | H24: No. of Students | I24: Units | J24: Units | K24: Total | L24: Total
I25: (lec) | J25: (lab) | K25: Units | L25: Hours
A26: IT Teachnical and Comp. Lab 1-2 Incharge | L26: 12
D27: TOTAL NUMBER OF UNITS/HRS (OTHER FUNCTIONS): | K27: =SUM(K26) -> 0 | L27: =SUM(L26) -> 12
A28: C. Consultation Hours
A29: Day | D29: Time | G29: Venue | K29: Number of hrs
A31: Mon | D31: 8AM-10AM | 1PM-5PM | G31: Computer Lab | K31: 6
A32: Tue | D32: 8AM-3PM | K32: 6
A33: Wed | D33: 8AM-4PM | K33: 7
D34: TOTAL NUMBER OF UNITS/HRS (CONSULTATION): | K34: =SUM(K31:L33) -> 19
D35: SUB-TOTAL (A-C) | K35: =L22+L27+K34 -> 40
A36: D. Overload
A37: Subj Code | B37: Descriptive Title | D37: Day | E37: Time | F37: Room | G37: Section | H37: No. of Students | I37: Units | J37: Units | K37: Total | L37: Total
I38: (lec) | J38: (lab) | K38: Units | L38: Hours
A39: IT 130 | B39: Networking 2 | D39: Thu | E39: 10:00 AM-01:00 PM | F39: Lab1 | G39: BSIT 4B | H39: 40 | L39: 1
D40: Thu | E40: 03:00 PM-05:00 PM | F40: 20
A41: IT 102 | B41: Computer Programming 1 | D41: Sat | E41: 07:00 PM-10:00 AM | F41: BSIT 1D | G41: Lab2 | H41: 40 | I41: 2 | J41: 1 | K41: 3 | L41: 5
D42: Fri | E42: 04:00 PM-06:00 PM | G42: Lab2
A43: IT 130 | B43: Networking 2 | D43: Wed | E43: 04:00 PM-07:00 PM | F43: Lab1 | G43: BSIT 4C | H43: 40 | I43: 2 | J43: 1 | K43: 3 | L43: 5
...

Sheet DelRosario J
A1: TCC-ADMN-Form 001
A2: TAGOLOAN COMMUNITY COLLEGE
A3: Baluarte, Tagoloan Misamis Oriental
A4: (08822)750-835
A5: Member: Association of Local Colleges & Universities (ALCU)
A6: Individual Faculty Load Sheet
A7: 1st Term Academic Year 2023 - 2024
A9: Surname: Del Rosario Given Name: Jefrey MI:
A10: Employment Status: (Put X)
C11: Regular | J11: Contractual
C13: Probationary | J13: Part-Time
A14: TEACHING LOAD
A15: A. Basic Load/Built-In
A16: Subj Code | B16: Descriptive Title | D16: Day | E16: Time | F16: Room | G16: Section | H16: No. of Students | I16: Units | J16: Units | K16: Total | L16: Total
I17: (lec) | J17: (lab) | K17: Units | L17: Hours
A18: IT 122 | B18: Computer Application | D18: TTH | E18: 06:30-08:30PM | F18: Lab3 | G18: BSET AT 2A | H18: 40 | I18: 4 | J18: 0 | K18: 3 | L18: 4
A19: IT 122 | B19: Integrative Programming & Technologies 2 | D19: Tue | E19: 07:00 AM-10:00 AM | F19: Lab2 | G19: BSIT 3B | H19: 40 | I19: 2 | J19: 1 | K19: 3 | L19: 5
D20: Mon | E20: 07:00 AM-09:00 AM | F20: 20
A21: IT 110 | B21: Object Oriented Programming (OOP) | D21: Fri | E21: 10:00 AM-01:00 PM | F21: Lab4 | G21: BSIT 2D | H21: 40 | I21: 3 | J21: 3 | K21: 5 | L21: 5
D22: Wed | E22: 9:00 AM-11:00 AM | F22: Lab4
A23: IT 110 | B23: Object Oriented Programming (OOP) | D23: Mon | E23: 04:00 PM-07:00 PM | F23: Lab3 | G23: BSIT 2B | H23: 40 | I23: 2 | J23: 1 | K23: 3 | L23: 5
D24: Tue | E24: 02:00 PM-04:00 PM | F24: Lab3
A25: IT 103 | B25: Integrated Application Software | D25: Thu | E25: 01:00 PM-04:00 PM | F25: Lab1 | G25: BSIT 1A | H25: 40 | I25: 2 | J25: 1 | K25: 3 | L25: 2
D26: Thu | E26: 04:00 PM-06:00 PM | F26: Lab1
E27: TOTAL NUMBER OF UNITS/HRS (BASIC) : | K27: =SUM(K18:K26) -> 17 | L27: =SUM(L18:L26) -> 21
A28: B. Other Academic-Related Functions
A29: Subj Code | B29: Descriptive Title | D29: Day | E29: Time | H29: No. of Students | I29: Units | J29: Units | K29: Total | L29: Total
I30: (lec) | J30: (lab) | K30: Units | L30: Hours
D32: TOTAL NUMBER OF UNITS/HRS (OTHER FUNCTIONS): | K32: =SUM(K31) -> 0 | L32: =SUM(L31) -> 0
A33: C. Consultation Hours
A34: Day | D34: Time | G34: Venue | K34: Number of hrs
A36: Tue | D36: 10:00 - 5:00 PM | G36: Computer Lab/IT Office | K36: 6
A37: Mon | D37: 8:00-12PM | K37: 4
A38: Wed | D38: 8:00-12PM | K38: 4
A39: Thu | D39: 1:00-2PM | K39: 1
A40: Fri | D40: 8:00-12PM | K40: 4
D41: TOTAL NUMBER OF UNITS/HRS (CONSULTATION): | K41: 19
D42: SUB-TOTAL (A-C) | K42: =L27+L32+K41 -> 40
A43: D. Overload
A44: Subj Code | B44: Descriptive Title | D44: Day | E44: Time | F44: Room | G44: Section | H44: No. of Students | I44: Units | J44: Units | K44: Total | L44: Total
...

Sheet Eduave G
A1: TCC-ADMN-Form 001
A2: TAGOLOAN COMMUNITY COLLEGE
A3: Baluarte, Tagoloan Misamis Oriental
A4: (08822)750-835
A5: Member: Association of Local Colleges & Universities (ALCU)
A6: Individual Faculty Load Sheet
A7: 1st Term Academic Year 2023 - 2024
A9: Surname: Eduave Given Name: Geleen MI: O
A10: Employment Status: (Put X)
C11: Regular | J11: Contractual
C13: Probationary | J13: Part-Time
A14: TEACHING LOAD
A15: A. Basic Load/Built-In
A16: Subj Code | B16: Descriptive Title | D16: Day | E16: Time | F16: Room | G16: Section | H16: No. of Students | I16: Units | J16: Units | K16: Total | L16: Total
I17: (lec) | J17: (lab) | K17: Units | L17: Hours
A18: GEE 9 | B18: Technoprenuership (The Entrepreneurial Mind) | D18: MW | E18: 08:30 AM-10:00 PM | F18: Online | G18: BSIT 3C | H18: 40 | I18: 3 | J18: 0 | K18: 3 | L18: 3
A19: GEE 9 | B19: Technoprenuership (The Entrepreneurial Mind) | D19: Sat | E19: 07:00 AM-10:00 AM | F19: Online | G19: BSIT 3D | H19: 40 | I19: 3 | J19: 0 | K19: 3 | L19: 3
E20: TOTAL NUMBER OF UNITS/HRS (BASIC) : | K20: =SUM(K18:K19) -> 6 | L20: =SUM(L18:L19) -> 6
A21: B. Other Academic-Related Functions
A22: Subj Code | B22: Descriptive Title | D22: Day | E22: Time | H22: No. of Students | I22: Units | J22: Units | K22: Total | L22: Total
I23: (lec) | J23: (lab) | K23: Units | L23: Hours
A24: College Secretary | L24: 15
D25: TOTAL NUMBER OF UNITS/HRS (OTHER FUNCTIONS): | K25: =SUM(K24) -> 0 | L25: =SUM(L24) -> 15
A26: C. Consultation Hours
A27: Day | D27: Time | G27: Venue | K27: Number of hrs
A29: Tue | D29: 1:00-5:00PM | 8:00-10:00 AM | G29: IT Office | K29: 6
A30: Thu | D30: 1:00-5:00PM | 8:00-10:00 AM | K30: 6
A31: Fri | D31: 8:00-4:00PM | K31: 7
D32: TOTAL NUMBER OF UNITS/HRS (CONSULTATION): | K32: =SUM(K29:L31) -> 19
D33: SUB-TOTAL (A-C) | K33: =L20+L25+K32 -> 40
A34: D. Overload
A35: Subj Code | B35: Descriptive Title | D35: Day | E35: Time | F35: Room | G35: Section | H35: No. of Students | I35: Units | J35: Units | K35: Total | L35: Total
I36: (lec) | J36: (lab) | K36: Units | L36: Hours
A37: GEE 9 | B37: Technoprenuership (The Entrepreneurial Mind) | D37: MW | E37: 02:30 PM-04:00 PM | F37: Online | G37: BSIT 3B | H37: 40 | I37: 3 | J37: 0 | K37: 3 | L37: 3
A38: GEE 9 | B38: Technoprenuership (The Entrepreneurial Mind) | D38: TTH | E38: 10:00 AM-12:30 AM | F38: Online | G38: BSIT 3A | H38: 40 | I38: 3 | J38: 0 | K38: 3 | L38: 3
A39: IT 100 | B39: Introduction to Computer Concepts and Fundamentals | D39: SAT | E39: 01:00-04:00PM | F39: 10 A | G39: BSCRIM 2C | H39: 40 | I39: 3 | J39: 3 | K39: 3 | L39: 3
A40: IT 100 | B40: Introduction to Computer Concepts and Fundamentals | D40: SAT | E40: 10:00-01:00PM | F40: 10 A | G40: BSCRIM 2B | H40: 40 | I40: 3 | J40: 3 | K40: 3 | L40: 3
D41: TOTAL NUMBER OF UNITS / HRS (OVERLOAD) | K41: =SUM(K37:K40) -> 12 | L41: =SUM(L37:L40) -> 12
D42: GRAND TOTAL NUMBER OF UNITS/HRS (A-D) | K42: =SUM(K20,K25,K41) -> 18 | L42: =(L20+L25+K32+L41) -> 52
A44: Prepared by: | H44: Noted:
...

Sheet Llemit A
A1: TCC-ADMN-Form 001
A2: TAGOLOAN COMMUNITY COLLEGE
A3: Baluarte, Tagoloan Misamis Oriental
A4: (08822)750-835
A5: Member: Association of Local Colleges & Universities (ALCU)
A6: Individual Faculty Load Sheet
A7: 1st Term Academic Year 2023 - 2024
A9: Surname: Llemit Given Name: Arnel MI: S
A10: Employment Status: (Put X)
C11: Regular | J11: Contractual
C13: Probationary | J13: Part-Time
A14: TEACHING LOAD
A15: A. Basic Load/Built-In
A16: Subj Code | B16: Descriptive Title | D16: Day | E16: Time | F16: Room | G16: Section | H16: No. of Students | I16: Units | J16: Units | K16: Total | L16: Total
I17: (lec) | J17: (lab) | K17: Units | L17: Hours
A18: IT Elec 2 | B18: Computer Graphics | D18: Mon | E18: 07:00 AM-10:00 AM | F18: Lab2 | G18: BSIT 3A | H18: 40 | I18: 2 | J18: 1 | K18: 3 | L18: 5
D19: Mon | E19: 11:00 AM-01:00 PM | F19: 20
A20: IT Elec 2 | B20: Computer Graphics | D20: Tue | E20: 10:00 AM-01:00 PM | F20: Lab2 | G20: BSIT 3B | H20: 40 | I20: 2 | J20: 1 | K20: 3 | L20: 1
D21: Wed | E21: 07:00 AM-09:00 AM | F21: 20
E22: TOTAL NUMBER OF UNITS/HRS (BASIC) : | K22: =SUM(K18:K42) -> 12 | L22: =SUM(L18:L21) -> 6
A23: B. Other Academic-Related Functions
A24: Subj Code | B24: Descriptive Title | D24: Day | E24: Time | H24: No. of Students | I24: Units | J24: Units | K24: Total | L24: Total
I25: (lec) | J25: (lab) | K25: Units | L25: Hours
A26: UniFAST Director | K26: 15 | L26: 15
D27: TOTAL NUMBER OF UNITS/HRS (OTHER FUNCTIONS): | K27: =SUM(K26) -> 15 | L27: =SUM(L26) -> 15
A28: C. Consultation Hours
A29: Day | D29: Time | G29: Venue | K29: Number of hrs
A31: Tue | D31: 10:00 - 5:00 PM | G31: IT Office | K31: 6
A32: Mon | D32: 8:00-12PM | K32: 4
A33: Wed | D33: 8:00-12PM | K33: 4
A34: Thu | D34: 1:00-2PM | K34: 1
A35: Fri | D35: 8:00-12PM | K35: 4
D36: TOTAL NUMBER OF UNITS/HRS (CONSULTATION): | K36: =SUM(K31:L35) -> 19
D37: SUB-TOTAL (A-C) | K37: =L22+L27+K36 -> 40
A38: D. Overload
A39: Subj Code | B39: Descriptive Title | D39: Day | E39: Time | F39: Room | G39: Section | H39: No. of Students | I39: Units | J39: Units | K39: Total | L39: Total
I40: (lec) | J40: (lab) | K40: Units | L40: Hours
A41: IT Elec 2 | B41: Computer Graphics | D41: Fri | E41: 07:00 AM-10:00 AM | F41: Lab2 | G41: BSIT 3D | H41: 40 | L41: 4
D42: Tue | E42: 07:00 AM-09:00 AM | F42: 20
A43: IT 100 | B43: Introduction to Computer Concepts and Fundamentals | D43: SUN | E43: 01:00-04:00PM | F43: 11 B | G43: BSCRIM 2G | H43: 40 | I43: 3 | J43: 3 | K43: 3 | L43: 3
...

Sheet Molawan A
A1: TCC-ADMN-Form 001
A2: TAGOLOAN COMMUNITY COLLEGE
A3: Baluarte, Tagoloan Misamis Oriental
A4: (08822)750-835
A5: Member: Association of Local Colleges & Universities (ALCU)
A6: Individual Faculty Load Sheet
A7: 1st Term Academic Year 2023 - 2024
A9: Surname: Molawan Given Name: Aldrin MI: T
A10: Employment Status: (Put X)
C11: Regular | J11: Contractual
C13: Probationary | J13: Part-Time
A14: TEACHING LOAD
A15: A. Basic Load/Built-In
A16: Subj Code | B16: Descriptive Title | D16: Day | E16: Time | F16: Room | G16: Section | H16: No. of Students | I16: Units | J16: Units | K16: Total | L16: Total
I17: (lec) | J17: (lab) | K17: Units | L17: Hours
A18: IT 111 | B18: Social Issues & Professional Issues | D18: Mon | E18: 10:00 AM-01:00 PM | F18: Online | G18: BSIT 2E | H18: 40 | I18: 3 | J18: 0 | K18: 3 | L18: 3
A19: IT 108 | B19: Data Structures & Algorithms | D19: Thu | E19: 11:00 AM-01:00 PM | F19: Lab4 | G19: BSIT 2C | H19: 40 | I19: 2 | J19: 1 | K19: 3 | L19: 5
D20: Tue | E20: 09:00 PM-11:00 AM | F20: Lab4
A21: IT 101 | B21: Introduction To Computing | D21: Fri | E21: 01:00 PM-04:00 PM | F21: Lab1 | G21: BSIT 1B | H21: 40 | I21: 2 | J21: 1 | K21: 3 | L21: 5
D22: Thu | E22: 07:00 AM-09:00 AM | F22: Lab4
A23: IT 101 | B23: Introduction To Computing | D23: Tue | E23: 04:00 PM-07:00 PM | F23: Lab2 | G23: BSIT 1C | H23: 40 | I23: 2 | J23: 1 | K23: 3 | L23: 5
D24: Wed | E24: 04:00 PM-06:00 PM | F24: Lab2
A25: IT 101 | B25: Introduction To Computing | D25: Tue | E25: 01:00 PM-04:00 PM | F25: Lab1 | G25: BSIT 1A | H25: 40 | I25: 2 | J25: 1 | K25: 3 | L25: 3
D26: Mon | E26: 01:00 PM-03:00 PM | F26: Lab2
E27: TOTAL NUMBER OF UNITS/HRS (BASIC) : | K27: =SUM(K18:K26) -> 15 | L27: =SUM(L18:L26) -> 21
A28: B. Other Academic-Related Functions
A29: Subj Code | B29: Descriptive Title | D29: Day | E29: Time | H29: No. of Students | I29: Units | J29: Units | K29: Total | L29: Total
I30: (lec) | J30: (lab) | K30: Units | L30: Hours
D32: TOTAL NUMBER OF UNITS/HRS (OTHER FUNCTIONS): | K32: =SUM(K31) -> 0 | L32: =SUM(L31) -> 0
A33: C. Consultation Hours
A34: Day | D34: Time | G34: Venue | K34: Number of hrs
A36: Mon | D36: 8AM-12PM | 4PM-5PM | G36: Computer Lab/IT Office | K36: 5
A37: Tue | D37: 7:00-9PM | K37: 1
A38: Wed | D38: 8AM-12PM | K38: 4
A39: Thu | D39: 12AM-2PM | K39: 3
A40: Fri | D40: 8AM-1PM | 5PM-7PM | K40: 6
D41: TOTAL NUMBER OF UNITS/HRS (CONSULTATION): | K41: =SUM(K36:L40) -> 19
D42: SUB-TOTAL (A-C) | K42: =L27+L32+K41 -> 40
A43: D. Overload
A44: Subj Code | B44: Descriptive Title | D44: Day | E44: Time | F44: Room | G44: Section | H44: No. of Students | I44: Units | J44: Units | K44: Total | L44: Total
...

Sheet Oyok A
A1: TCC-ADMN-Form 001
A2: TAGOLOAN COMMUNITY COLLEGE
A3: Baluarte, Tagoloan Misamis Oriental
A4: (08822)750-835
A5: Member: Association of Local Colleges & Universities (ALCU)
A6: Individual Faculty Load Sheet
A7: 1st Term Academic Year 2023 - 2024
A9: Surname: Oyok Given Name: Azmie MI: A
A10: Employment Status: (Put X)
C11: Regular | J11: Contractual
C13: Probationary | J13: Part-Time
A14: TEACHING LOAD
A15: A. Basic Load/Built-In
A16: Subj Code | B16: Descriptive Title | D16: Day | E16: Time | F16: Room | G16: Section | H16: No. of Students | I16: Units | J16: Units | K16: Total | L16: Total
I17: (lec) | J17: (lab) | K17: Units | L17: Hours
A18: IT 128 | B18: System Administration and Maintenance | D18: Wed | E18: 07:00 AM-10:00 AM | F18: Lab1 | G18: BSIT 4A | H18: 40 | I18: 2 | J18: 1 | K18: 3 | L18: 5
D19: Tue | E19: 11:00 AM-01:00 PM | F19: 20
A20: IT 128 | B20: System Administration and Maintenance | D20: Thu | E20: 07:00 AM-10:00 AM | F20: Lab1 | G20: BSIT 4B | H20: 40 | I20: 2 | J20: 1 | K20: 3 | L20: 4
D21: Thu | E21: 11:00 AM-01:00 PM | F21: 20
E22: TOTAL NUMBER OF UNITS/HRS (BASIC) : | K22: =SUM(K18:K21) -> 6 | L22: =SUM(L18:L21) -> 9
A23: B. Other Academic-Related Functions
A24: Subj Code | B24: Descriptive Title | D24: Day | E24: Time | H24: No. of Students | I24: Units | J24: Units | K24: Total | L24: Total
I25: (lec) | J25: (lab) | K25: Units | L25: Hours
A26: IT Teachnical and Comp. Lab 1 Incharge | L26: 12
D27: TOTAL NUMBER OF UNITS/HRS (OTHER FUNCTIONS): | K27: =SUM(K26) -> 0 | L27: =SUM(L26) -> 12
A28: C. Consultation Hours
A29: Day | D29: Time | G29: Venue | K29: Number of hrs
A31: Mon | D31: 8AM-9AM | 1PM-3PM | G31: Computer Lab/IT Office | K31: 3
A32: Tue | D32: 8AM-11PM | 2PM-6PM | K32: 7
A33: Wed | D33: 1:00-5PM | K33: 4
A34: Fri | D34: 8:00-10AM | 2-5PM | K34: 5
D35: TOTAL NUMBER OF UNITS/HRS (CONSULTATION): | K35: =SUM(K31:L34) -> 19
D36: SUB-TOTAL (A-C) | K36: =L22+L27+K35 -> 40
A37: D. Overload
A38: Subj Code | B38: Descriptive Title | D38: Day | E38: Time | F38: Room | G38: Section | H38: No. of Students | I38: Units | J38: Units | K38: Total | L38: Total
I39: (lec) | J39: (lab) | K39: Units | L39: Hours
A40: IT 128 | B40: System Administration and Maintenance | D40: Thu | E40: 07:00 AM-10:00 AM | F40: Lab1 | G40: BSIT 4B | H40: 40 | L40: 1
D41: Thu | E41: 11:00 AM-01:00 PM | F41: 20
A42: IT 102 | B42: Computer Programming 1 | D42: Sat | E42: 01:00 PM-04:00 PM | F42: BSIT 1C | G42: Lab1 | H42: 40 | I42: 2 | J42: 1 | K42: 3 | L42: 5
D43: Sat | E43: 04:00 PM-07:00 PM | G43: Lab1
...

Sheet Pada J
A1: TCC-ADMN-Form 001
A2: TAGOLOAN COMMUNITY COLLEGE
A3: Baluarte, Tagoloan Misamis Oriental
A4: (08822)750-835
A5: Member: Association of Local Colleges & Universities (ALCU)
A6: Individual Faculty Load Sheet
A7: 1st Term Academic Year 2023 - 2024
A9: Surname: Pada Given Name: Jan James MI: M
A10: Employment Status: (Put X)
C11: Regular | J11: Contractual
C13: Probationary | J13: Part-Time
A14: TEACHING LOAD
A15: A. Basic Load/Built-In
A16: Subj Code | B16: Descriptive Title | D16: Day | E16: Time | F16: Room | G16: Section | H16: No. of Students | I16: Units | J16: Units | K16: Total | L16: Total
I17: (lec) | J17: (lab) | K17: Units | L17: Hours
A18: IT 121 | B18: Information Management 2 | D18: Fri | E18: 10:00 AM-01:00 PM | F18: BSIT 3D | G18: Lab2 | H18: 40 | I18: 2 | J18: 1 | K18: 3 | L18: 5
D19: Tue | E19: 01:00 PM-03:00 PM | G19: 20
A20: IT 121 | B20: Information Management 2 | D20: Wed | E20: 07:00 AM-10:00 AM | F20: BSIT 3A | G20: Lab2 | H20: 40 | I20: 2 | J20: 1 | K20: 3 | L20: 5
D21: Wed | E21: 03:00 PM-05:00 PM | G21: 20
A22: IT 121 | B22: Information Management 2 | D22: Thu | E22: 07:00 AM-10:00 AM | F22: BSIT 3B | G22: Lab2 | H22: 40 | I22: 2 | J22: 1 | K22: 3 | L22: 5
D23: Wed | E23: 10:00 AM-12:00 PM | G23: 20
A24: IT 103 | B24: Integrated Application Software | D24: Thu | E24: 01:00 PM-03:00 PM | F24: Lab2 | G24: BSIT 1C | H24: 40 | I24: 2 | J24: 1 | K24: 3 | L24: 5
D25: Fri | E25: 04:00 PM-07:00 PM | F25: Lab1
A26: IT 103 | B26: Integrated Application Software | D26: Fri | E26: 01:00 AM-3:00 PM | F26: 20B | G26: BSIT 1F | H26: 40 | I26: 2 | J26: 1 | K26: 3 | L26: 1
D27: Sun | E27: 10:00 AM-01:00 AM | F27: Lab3 | R27: ``
E28: TOTAL NUMBER OF UNITS/HRS (BASIC) : | K28: =SUM(K18:K27) -> 15 | L28: =SUM(L18:L27) -> 21
A29: B. Other Academic-Related Functions
A30: Subj Code | B30: Descriptive Title | D30: Day | E30: Time | H30: No. of Students | I30: Units | J30: Units | K30: Total | L30: Total
I31: (lec) | J31: (lab) | K31: Units | L31: Hours
D33: TOTAL NUMBER OF UNITS/HRS (OTHER FUNCTIONS): | K33: =SUM(K32) -> 0 | L33: =SUM(L32) -> 0
A34: C. Consultation Hours
A35: Day | D35: Time | G35: Venue | K35: Number of hrs
A37: Mon | D37: 8AM-3PM | G37: Computer Lab/IT Office | K37: 6
A38: Tue | D38: 10AM-11PM | 1PM-2PM | K38: 2
A39: Wed | D39: 8AM-4PM | K39: 6
A40: Thu | D40: 1:00-2PM | K40: 1
A41: Thu | D41: 9:00-1PM | K41: 4
D42: TOTAL NUMBER OF UNITS/HRS (CONSULTATION): | K42: =SUM(K37:L41) -> 19
D43: SUB-TOTAL (A-C) | K43: =L28+L33+K42 -> 40
A44: D. Overload
...

Sheet Padilla J
A1: TCC-ADMN-Form 001
A2: TAGOLOAN COMMUNITY COLLEGE
A3: Baluarte, Tagoloan Misamis Oriental
A4: (08822)750-835
A5: Member: Association of Local Colleges & Universities (ALCU)
A6: Individual Faculty Load Sheet
A7: 1st Term Academic Year 2023 - 2024
A9: Surname: Padilla Given Name: Joniel MI: E
A10: Employment Status: (Put X)
C11: Regular | J11: Contractual
C13: Probationary | J13: Part-Time
A14: TEACHING LOAD
A15: A. Basic Load/Built-In
A16: Subj Code | B16: Descriptive Title | D16: Day | E16: Time | F16: Room | G16: Section | H16: No. of Students | I16: Units | J16: Units | K16: Total | L16: Total
I17: (lec) | J17: (lab) | K17: Units | L17: Hours
A18: IT 110 | B18: Object Oriented Programming (OOP) | D18: Mon | E18: 07:00 AM-10:00 AM | F18: Lab3 | G18: BSIT 2A | H18: 40 | I18: 2 | J18: 1 | K18: 3 | L18: 5
D19: Tue | E19: 07:00 AM-09:00 AM | F19: Lab3
A20: IT 110 | B20: Object Oriented Programming (OOP) | D20: Fri | E20: 02:00 PM-05:00 PM | F20: Lab4 | G20: BSIT 2C | H20: 40 | I20: 2 | J20: 1 | K20: 3 | L20: 4
D21: Wed | E21: 11:00 AM-01:00 PM | F21: Lab4
E22: TOTAL NUMBER OF UNITS/HRS (BASIC) : | K22: =SUM(K18:K21) -> 6 | L22: =SUM(L18:L21) -> 9
A23: B. Other Academic-Related Functions
A24: Subj Code | B24: Descriptive Title | D24: Day | E24: Time | H24: No. of Students | I24: Units | J24: Units | K24: Total | L24: Total
I25: (lec) | J25: (lab) | K25: Units | L25: Hours
A26: IT Administrator's Associate | L26: 12
D27: TOTAL NUMBER OF UNITS/HRS (OTHER FUNCTIONS): | K27: =SUM(K26) -> 0 | L27: =SUM(L26) -> 12
A28: C. Consultation Hours
A29: Day | D29: Time | G29: Venue | K29: Number of hrs
A31: Mon | D31: 10AM-1PM | 4PM-6PM | G31: Computer Lab/IT Office | K31: 5
A32: Tue | D32: 9AM-6PM | K32: 8
A33: Wed | D33: 8:00-11PM | 1PM-5PM | K33: 6
D34: TOTAL NUMBER OF UNITS/HRS (CONSULTATION): | K34: =SUM(K31:L33) -> 19
D35: SUB-TOTAL (A-C) | K35: =L22+L27+K34 -> 40
A36: D. Overload
A37: Subj Code | B37: Descriptive Title | D37: Day | E37: Time | F37: Room | G37: Section | H37: No. of Students | I37: Units | J37: Units | K37: Total | L37: Total
I38: (lec) | J38: (lab) | K38: Units | L38: Hours
A39: IT 110 | B39: Object Oriented Programming (OOP) | D39: Fri | E39: 02:00 PM-05:00 PM | F39: Lab4 | G39: BSIT 2C | H39: 40 | L39: 1
D40: Wed | E40: 11:00 AM-01:00 PM | F40: Lab4
A41: IT 103 | B41: Integrated Application Software | D41: Thu | E41: 01:00 PM-04:00 PM | F41: Lab1 | G41: BSIT 1A | H41: 40 | I41: 2 | J41: 1 | K41: 3 | L41: 5
D42: Thu | E42: 04:00 PM-06:00 PM | F42: Lab1
A43: IT 110 | B43: Object Oriented Programming (OOP) | D43: Mon | E43: 01:00 PM-04:00 PM | F43: Lab4 | G43: BSIT 2E | H43: 40 | I43: 3 | J43: 3 | K43: 5 | L43: 5
...

Sheet Perez N
A1: TCC-ADMN-Form 001
A2: TAGOLOAN COMMUNITY COLLEGE
A3: Baluarte, Tagoloan Misamis Oriental
A4: (08822)750-835
A5: Member: Association of Local Colleges & Universities (ALCU)
A6: Individual Faculty Load Sheet
A7: 1st Term Academic Year 2023 - 2024
A9: Surname: Perez Given Name: Nikko MI: A
A10: Employment Status: (Put X)
C11: Regular | J11: Contractual
C13: Probationary | J13: Part-Time
A14: TEACHING LOAD
A15: A. Basic Load/Built-In
A16: Subj Code | B16: Descriptive Title | D16: Day | E16: Time | F16: Room | G16: Section | H16: No. of Students | I16: Units | J16: Units | K16: Total | L16: Total
I17: (lec) | J17: (lab) | K17: Units | L17: Hours
A18: IT 109 | B18: Fundamentals of Database Systems | D18: Mon | E18: 10:00 AM-01:00 PM | F18: Lab3 | G18: BSIT 2A | H18: 40 | I18: 2 | J18: 1 | K18: 3 | L18: 5
D19: Tue | E19: 09:00 AM-11:00 AM | F19: Lab3
A20: IT 109 | B20: Fundamentals of Database Systems | D20: Mon | E20: 01:00 PM-04:00 PM | F20: Lab3 | G20: BSIT 2B | H20: 40 | I20: 2 | J20: 1 | K20: 3 | L20: 5
D21: Tue | E21: 12:00 PM-02:00 PM | F21: Lab3
A22: IT 109 | B22: Fundamentals of Database Systems | D22: Fri | E22: 11:00 AM-01:00 PM | F22: Lab4 | G22: BSIT 2C | H22: 40 | I22: 2 | J22: 1 | K22: 3 | L22: 5
D23: Wed | E23: 01:00 PM-03:00 PM | F23: Lab4
A24: IT 109 | B24: Fundamentals of Database Systems | D24: Mon | E24: 07:00 AM-10:00 AM | F24: Lab4 | G24: BSIT 2D | H24: 40 | I24: 2 | J24: 1 | K24: 3 | L24: 5
D25: Wed | E25: 07:00 AM-09:00 AM | F25: Lab4
A26: IT 109 | B26: Fundamentals of Database Systems | D26: Mon | E26: 04:00 PM-07:00 PM | F26: Lab4 | G26: BSIT 2E | H26: 40 | I26: 2 | J26: 1 | K26: 3 | L26: 1
D27: Wed | E27: 03:00 PM-05:00 PM | F27: Lab4
E28: TOTAL NUMBER OF UNITS/HRS (BASIC) : | K28: =SUM(K18:K27) -> 15 | L28: =SUM(L18:L27) -> 21
A29: B. Other Academic-Related Functions
A30: Subj Code | B30: Descriptive Title | D30: Day | E30: Time | H30: No. of Students | I30: Units | J30: Units | K30: Total | L30: Total
I31: (lec) | J31: (lab) | K31: Units | L31: Hours
D33: TOTAL NUMBER OF UNITS/HRS (OTHER FUNCTIONS): | K33: =SUM(K32) -> 0 | L33: =SUM(L32) -> 0
A34: C. Consultation Hours
A35: Day | D35: Time | G35: Venue | K35: Number of hrs
A37: Mon | D37: 8:00-10PM | G37: Computer Lab/IT Office | K37: 2
A38: Tue | D38: 7AM-9AM | 3PM-6PM | K38: 5
A39: Thu | D39: 10AM-6PM | K39: 9
A40: Fri | D40: 8AM-11AM | K40: 3
D41: TOTAL NUMBER OF UNITS/HRS (CONSULTATION): | K41: =SUM(K37:L40) -> 19
D42: SUB-TOTAL (A-C) | K42: =L28+L33+K41 -> 40
A43: D. Overload
A44: Subj Code | B44: Descriptive Title | D44: Day | E44: Time | F44: Room | G44: Section | H44: No. of Students | I44: Units | J44: Units | K44: Total | L44: Total
...

Sheet Razalo J
A1: TCC-ADMN-Form 001
A2: TAGOLOAN COMMUNITY COLLEGE
A3: Baluarte, Tagoloan Misamis Oriental
A4: (08822)750-835
A5: Member: Association of Local Colleges & Universities (ALCU)
A6: Individual Faculty Load Sheet
A7: 1st Term Academic Year 2023 - 2024
A9: Surname: Razalo Given Name: Janu Vincent MI: A
A10: Employment Status: (Put X)
C11: Regular | J11: Contractual
C13: Probationary | J13: Part-Time
A14: TEACHING LOAD
A15: A. Basic Load/Built-In
A16: Subj Code | B16: Descriptive Title | D16: Day | E16: Time | F16: Room | G16: Section | H16: No. of Students | I16: Units | J16: Units | K16: Total | L16: Total
I17: (lec) | J17: (lab) | K17: Units | L17: Hours
A18: IT 132 | B18: Capstone Project 2 | D18: Wed | E18: 01:00 PM-03:00 PM | F18: Online | G18: BSIT 4C | H18: 40 | I18: 3 | J18: 0 | K18: 3 | L18: 3
A19: IT 132 | B19: Capstone Project 2 | D19: Fri | E19: 01:00 PM-03:00 PM | F19: Online | G19: BSIT 4A | H19: 40 | I19: 3 | J19: 0 | K19: 3 | L19: 3
A20: IT 132 | B20: Capstone Project 2 | D20: Fri | E20: 03:00 PM-07:00 PM | F20: Online | G20: BSIT 4B | H20: 40 | I20: 3 | J20: 0 | K20: 3 | L20: 3
A21: IT 129 | B21: Information Assurance & Security 2 | D21: Tue | E21: 10:00 AM-01:00 PM | F21: Lab1 | G21: BSIT 4B | H21: 40 | I21: 2 | J21: 1 | K21: 3 | L21: 5
D22: Thu | E22: 01:00 PM-03:00 PM | F22: 20
A23: IT 129 | B23: Information Assurance & Security 2 | D23: Mon | E23: 01:00 PM-04:00 PM | F23: Lab1 | G23: BSIT 4C | H23: 40 | I23: 2 | J23: 1 | K23: 3 | L23: 5
D24: Fri | E24: 09:00 AM-11:00 AM | F24: 20
A25: IT 129 | B25: Information Assurance & Security 2 | D25: Mon | E25: 07:00 AM-10:00 AM | F25: Lab1 | G25: BSIT 4A | H25: 40 | I25: 2 | J25: 1 | K25: 3 | L25: 2
D26: Tue | E26: 01:00 PM-03:00 PM | F26: 20
E27: TOTAL NUMBER OF UNITS/HRS (BASIC) : | K27: =SUM(K18:K26) -> 18 | L27: =SUM(L18:L26) -> 21
A28: B. Other Academic-Related Functions
A29: Subj Code | B29: Descriptive Title | D29: Day | E29: Time | H29: No. of Students | I29: Units | J29: Units | K29: Total | L29: Total
I30: (lec) | J30: (lab) | K30: Units | L30: Hours
D32: TOTAL NUMBER OF UNITS/HRS (OTHER FUNCTIONS): | K32: =SUM(K31) -> 0 | L32: =SUM(L31) -> 0
A33: C. Consultation Hours
A34: Day | D34: Time | G34: Venue | K34: Number of hrs
A36: Tue | D36: 10:00 - 5:00 PM | G36: Computer Lab/IT Office | K36: 6
A37: Mon | D37: 8:00-12PM | K37: 4
A38: Wed | D38: 8:00-12PM | K38: 4
A39: Thu | D39: 1:00-2PM | K39: 1
A40: Fri | D40: 8:00-12PM | K40: 4
D41: TOTAL NUMBER OF UNITS/HRS (CONSULTATION): | K41: 19
D42: SUB-TOTAL (A-C) | K42: =L27+L32+K41 -> 40
A43: D. Overload
A44: Subj Code | B44: Descriptive Title | D44: Day | E44: Time | F44: Room | G44: Section | H44: No. of Students | I44: Units | J44: Units | K44: Total | L44: Total
...

Sheet Roa N
A1: TCC-ADMN-Form 001
A2: TAGOLOAN COMMUNITY COLLEGE
A3: Baluarte, Tagoloan Misamis Oriental
A4: (08822)750-835
A5: Member: Association of Local Colleges & Universities (ALCU)
A6: Individual Faculty Load Sheet
A7: 1st Term Academic Year 2023 - 2024
A9: Surname: Roa Given Name: Neptale III MI: S
A10: Employment Status: (Put X)
C11: Regular | J11: Contractual
C13: Probationary | J13: Part-Time
A14: TEACHING LOAD
A15: A. Basic Load/Built-In
A16: Subj Code | B16: Descriptive Title | D16: Day | E16: Time | F16: Room | G16: Section | H16: No. of Students | I16: Units | J16: Units | K16: Total | L16: Total
I17: (lec) | J17: (lab) | K17: Units | L17: Hours
A18: IT 107 | B18: Application Development & Emerging Technologies | D18: Wed | E18: 10:00 AM-01:00 PM | F18: Lab3 | G18: BSIT 2A | H18: 40 | I18: 2 | J18: 1 | K18: 3 | L18: 5
D19: Thu | E19: 07:00 AM-09:00 AM | F19: Lab3 | H19: 40
A20: IT 107 | B20: Application Development & Emerging Technologies | D20: Wed | E20: 01:00 PM-04:00 PM | F20: Lab3 | G20: BSIT 2B | H20: 40 | I20: 2 | J20: 1 | K20: 3 | L20: 5
D21: Fri | E21: 04:00 PM-06:00 PM | F21: Lab3 | H21: 40
A22: IT 107 | B22: Application Development & Emerging Technologies | D22: Thu | E22: 11:00 AM-01:00 PM | F22: Lab4 | G22: BSIT 2C | H22: 40 | I22: 2 | J22: 1 | K22: 3 | L22: 5
D23: Tue | E23: 11:00 AM-01:00 PM | F23: Lab4 | H23: 40
A24: IT 107 | B24: Application Development & Emerging Technologies | D24: Fri | E24: 07:00 AM-10:00 AM | F24: Lab4 | G24: BSIT 2D | H24: 40 | I24: 2 | J24: 1 | K24: 3 | L24: 5
D25: Tue | E25: 07:00 AM-09:00 AM | F25: Lab4 | H25: 40
A26: IT 107 | B26: Application Development & Emerging Technologies | D26: Fri | E26: 01:00 PM-04:00 PM | F26: Lab4 | G26: BSIT 2E | H26: 40 | I26: 2 | J26: 1 | K26: 3 | L26: 1
D27: Tue | E27: 03:00 PM-05:00 PM | F27: Lab4 | H27: 40
E28: TOTAL NUMBER OF UNITS/HRS (BASIC) : | K28: =SUM(K18:K27) -> 15 | L28: =SUM(L18:L27) -> 21
A29: B. Other Academic-Related Functions
A30: Subj Code | B30: Descriptive Title | D30: Day | E30: Time | H30: No. of Students | I30: Units | J30: Units | K30: Total | L30: Total
I31: (lec) | J31: (lab) | K31: Units | L31: Hours
D33: TOTAL NUMBER OF UNITS/HRS (OTHER FUNCTIONS): | K33: =SUM(K32) -> 0 | L33: =SUM(L32) -> 0
A34: C. Consultation Hours
A35: Day | D35: Time | G35: Venue | K35: Number of hrs
A37: Mon | D37: 7AM-3PM | G37: Computer Lab/IT Office | K37: 7
A38: Wed | D38: 1PM-6PM | K38: 5
A39: Thu | D39: 1PM-6PM | K39: 5
A40: Fri | D40: 10AM-12PM | K40: 2
D41: TOTAL NUMBER OF UNITS/HRS (CONSULTATION): | K41: =SUM(K37:L40) -> 19
D42: SUB-TOTAL (A-C) | K42: =L28+L33+K41 -> 40
A43: D. Overload
A44: Subj Code | B44: Descriptive Title | D44: Day | E44: Time | F44: Room | G44: Section | H44: No. of Students | I44: Units | J44: Units | K44: Total | L44: Total
...

Sheet Tabada J
A1: TCC-ADMN-Form 001
A2: TAGOLOAN COMMUNITY COLLEGE
A3: Baluarte, Tagoloan Misamis Oriental
A4: (08822)750-835
A5: Member: Association of Local Colleges & Universities (ALCU)
A6: Individual Faculty Load Sheet
A7: 1st Term Academic Year 2023 - 2024
A9: Surname: Tabada Given Name: Jasmin MI: A
A10: Employment Status: (Put X)
C11: Regular | J11: Contractual
C13: Probationary | J13: Part-Time
A14: TEACHING LOAD
A15: A. Basic Load/Built-In
A16: Subj Code | B16: Descriptive Title | D16: Day | E16: Time | F16: Room | G16: Section | H16: No. of Students | I16: Units | J16: Units | K16: Total | L16: Total
I17: (lec) | J17: (lab) | K17: Units | L17: Hours
A18: Math1 | B18: College Algebra | D18: TTH | E18: 07:00 AM-08:30 AM | F18: Online | G18: BSIT 1A | H18: 40 | I18: 3 | J18: 0 | K18: 1 | L18: 3
A19: Math1 | B19: College Algebra | D19: MW | E19: 10:00 AM-11:30 AM | F19: Online | G19: BSIT 1D | H19: 40 | I19: 3 | J19: 0 | K19: 1 | L19: 3
A20: Math1 | B20: College Algebra | D20: TTH | E20: 01:00 PM-02:30 PM | F20: Online | G20: BSIT 1B | H20: 40 | I20: 3 | J20: 0 | K20: 1 | L20: 3
A21: Math1 | B21: College Algebra | D21: TTH | E21: 02:30 PM-04:00 PM | F21: Online | G21: BSIT 1C | H21: 40 | I21: 3 | J21: 0 | K21: 1 | L21: 3
A22: Math2 | B22: Plane Trigonometry | D22: MW | E22: 01:00 PM-02:30 PM | F22: Online | G22: BSIT 1C | H22: 40 | I22: 3 | J22: 0 | K22: 1 | L22: 3
A23: Math2 | B23: Plane Trigonometry | D23: MW | E23: 02:30 PM-04:00 PM | F23: Online | G23: BSIT 1D | H23: 40 | I23: 3 | J23: 0 | K23: 1 | L23: 3
A24: Math2 | B24: Plane Trigonometry | D24: TTH | E24: 08:30 AM-10:00 AM | F24: Online | G24: BSIT 1A | H24: 40 | I24: 3 | J24: 0 | K24: 1 | L24: 3
E25: TOTAL NUMBER OF UNITS/HRS (BASIC) : | K25: =SUM(K18:K24) -> 7 | L25: =SUM(L18:L24) -> 21
A26: B. Other Academic-Related Functions
A27: Subj Code | B27: Descriptive Title | D27: Day | E27: Time | H27: No. of Students | I27: Units | J27: Units | K27: Total | L27: Total
I28: (lec) | J28: (lab) | K28: Units | L28: Hours
D30: TOTAL NUMBER OF UNITS/HRS (OTHER FUNCTIONS): | K30: =SUM(K29) -> 0 | L30: =SUM(L29) -> 0
A31: C. Consultation Hours
A32: Day | D32: Time | G32: Venue | K32: Number of hrs
A34: Tue | D34: 10:00 - 5:00 PM | G34: Computer Lab/IT Office | K34: 6
A35: Mon | D35: 8:00-12PM | K35: 4
A36: Wed | D36: 8:00-12PM | K36: 4
A37: Thu | D37: 1:00-2PM | K37: 1
A38: Fri | D38: 8:00-12PM | K38: 4
D39: TOTAL NUMBER OF UNITS/HRS (CONSULTATION): | K39: 19
D40: SUB-TOTAL (A-C) | K40: =L25+L30+K39 -> 40
A41: D. Overload
A42: Subj Code | B42: Descriptive Title | D42: Day | E42: Time | F42: Room | G42: Section | H42: No. of Students | I42: Units | J42: Units | K42: Total | L42: Total
I43: (lec) | J43: (lab) | K43: Units | L43: Hours
A44: Math2 | B44: Plane Trigonometry | D44: MW | E44: 04:00 PM-05:30 PM | F44: BSIT 1B | G44: Online | H44: Online | I44: 3 | J44: 0 | K44: 1 | L44: 3
...

Sheet Waga KR
A1: TCC-ADMN-Form 001
A2: TAGOLOAN COMMUNITY COLLEGE
A3: Baluarte, Tagoloan Misamis Oriental
A4: (08822)750-835
A5: Member: Association of Local Colleges & Universities (ALCU)
A6: Individual Faculty Load Sheet
A7: 1st Term Academic Year 2023 - 2024
A9: Surname:Waga Given Name: Kay Rejoice MI: C
A10: Employment Status: (Put X)
C11: Regular | J11: Contractual
C13: Probationary | J13: Part-Time
A14: TEACHING LOAD
A15: A. Basic Load/Built-In
A16: Subj Code | B16: Descriptive Title | D16: Day | E16: Time | F16: Room | G16: Section | H16: No. of Students | I16: Units | J16: Units | K16: Total | L16: Total
I17: (lec) | J17: (lab) | K17: Units | L17: Hours
A18: IT 102 | B18: Computer Programming 1 | D18: Tue | E18: 04:00 PM-07:00 PM | F18: Lab1 | G18: BSIT 1A | H18: 40 | I18: 2 | J18: 1 | K18: 3 | L18: 5
D19: Mon | E19: 03:00 PM-05:00 PM | F19: Lab2
A20: IT 102 | B20: Computer Programming 1 | D20: Fri | E20: 01:00 PM-04:00 PM | F20: Lab1 | G20: BSIT 1B | H20: 40 | I20: 2 | J20: 1 | K20: 3 | L20: 5
D21: Thu | E21: 7:00 AM-09:00 AM | F21: Lab4
A22: IT 108 | B22: Data Structures & Algorithms | D22: Mon | E22: 10:00 AM-01:00 PM | F22: Lab4 | G22: BSIT 2D | H22: 40 | I22: 2 | J22: 1 | K22: 3 | L22: 5
D23: Tue | E23: 09:00 AM-11:00 AM | F23: Lab4
E24: TOTAL NUMBER OF UNITS/HRS (BASIC) : | K24: =SUM(K18:K23) -> 9 | L24: =SUM(L18:L23) -> 15
A25: B. Other Academic-Related Functions
A26: Subj Code | B26: Descriptive Title | D26: Day | E26: Time | H26: No. of Students | I26: Units | J26: Units | K26: Total | L26: Total
I27: (lec) | J27: (lab) | K27: Units | L27: Hours
A28: College Secretary | L28: 6
D29: TOTAL NUMBER OF UNITS/HRS (OTHER FUNCTIONS): | K29: =SUM(K28) -> 0 | L29: =SUM(L28) -> 6
A30: C. Consultation Hours
A31: Day | D31: Time | G31: Venue | K31: Number of hrs
A33: Mon | D33: 8:00-10AM | 1PM-2PM | G33: Computer Lab/IT Office | K33: 3
A34: Tue | D34: 8:00-9AM | 1PM-3PM | K34: 3
A35: Wed | D35: 10:00-6PM | K35: 8
A36: Thu | D36: 1:00-6PM | K36: 5
D37: TOTAL NUMBER OF UNITS/HRS (CONSULTATION): | K37: =SUM(K33:L36) -> 19
D38: SUB-TOTAL (A-C) | K38: =L24+L29+K37 -> 40
A39: D. Overload
A40: Subj Code | B40: Descriptive Title | D40: Day | E40: Time | F40: Room | G40: Section | H40: No. of Students | I40: Units | J40: Units | K40: Total | L40: Total
I41: (lec) | J41: (lab) | K41: Units | L41: Hours
A42: IT 108 | B42: Data Structures & Algorithms | D42: Wed | E42: 07:00 AM-10:00 AM | F42: Lab3 | G42: BSIT 2A | H42: 40 | I42: 2 | J42: 1 | K42: 3 | L42: 5
D43: Fri | E43: 07:00 AM-09:00 AM | F43: Lab3
...

Sheet Lagulay E
A1: TCC-ADMN-Form 001
A2: TAGOLOAN COMMUNITY COLLEGE
A3: Baluarte, Tagoloan Misamis Oriental
A4: (08822)750-835
A5: Member: Association of Local Colleges & Universities (ALCU)
A6: Individual Faculty Load Sheet
A7: 1st Term Academic Year 2023 - 2024
A9: Surname: Lagulay Given Name: Eldefonso MI: C
A10: Employment Status: (Put X)
C11: Regular | J11: Contractual
C13: Probationary | J13: Part-Time
A14: TEACHING LOAD
A15: A. Basic Load/Built-In
A16: Subj Code | B16: Descriptive Title | D16: Day | E16: Time | F16: Room | G16: Section | H16: No. of Students | I16: Units | J16: Units | K16: Total | L16: Total
I17: (lec) | J17: (lab) | K17: Units | L17: Hours
E19: TOTAL NUMBER OF UNITS/HRS (BASIC) : | K19: =SUM(K18:K18) -> 0 | L19: =SUM(L18:L18) -> 0
A20: B. Other Academic-Related Functions
A21: Subj Code | B21: Descriptive Title | D21: Day | E21: Time | H21: No. of Students | I21: Units | J21: Units | K21: Total | L21: Total
I22: (lec) | J22: (lab) | K22: Units | L22: Hours
D24: TOTAL NUMBER OF UNITS/HRS (OTHER FUNCTIONS): | K24: =SUM(K23) -> 0 | L24: =SUM(L23) -> 0
A25: C. Consultation Hours
A26: Day | D26: Time | G26: Venue | K26: Number of hrs
D29: TOTAL NUMBER OF UNITS/HRS (CONSULTATION):
D30: SUB-TOTAL (A-C) | K30: =L19+L24+K29 -> 0
A31: D. Overload
A32: Subj Code | B32: Descriptive Title | D32: Day | E32: Time | F32: Room | G32: Section | H32: No. of Students | I32: Units | J32: Units | K32: Total | L32: Total
I33: (lec) | J33: (lab) | K33: Units | L33: Hours
A34: IT 108 | B34: FUNDAMENTALS OF DATABASE SYSTEM | D34: SAT | E34: 01:00-04:00PM | F34: 23 | G34: BSBA 2F | H34: 40 | I34: 3 | J34: 0 | K34: 3 | L34: 3
A35: IT 100 | B35: Introduction to Computer Concepts and Fundamentals | D35: SAT | E35: 07:00-10:00AM | F35: 10 C | G35: BSCRIM 2E | H35: 40 | I35: 3 | J35: 3 | K35: 3 | L35: 3
A36: IT 100 | B36: Introduction to Computer Concepts and Fundamentals | D36: SAT | E36: 04:00 PM-07:00PM | F36: 10 B | G36: BSCRIM 2D | H36: 40 | I36: 3 | J36: 3 | K36: 3 | L36: 3
D37: TOTAL NUMBER OF UNITS / HRS (OVERLOAD) | K37: =SUM(K34:K36) -> 9 | L37: =SUM(L34:L36) -> 9
D38: GRAND TOTAL NUMBER OF UNITS/HRS (A-D) | K38: =SUM(K19,K24,K37) -> 9 | L38: =(L19+L24+K29+L37) -> 9
A40: Prepared by: | H40: Noted:
A42: Mr. Gabriel E. Casiño | H42: Ms. Merilyn A.Tangon
A43: Department Head | H43: Vice President for Academic Affairs
D45: Hon. Atty. Nadya Emano-Elipe
D46: OIC - President

Sheet Romero M
A1: TCC-ADMN-Form 001
A2: TAGOLOAN COMMUNITY COLLEGE
A3: Baluarte, Tagoloan Misamis Oriental
A4: (08822)750-835
A5: Member: Association of Local Colleges & Universities (ALCU)
A6: Individual Faculty Load Sheet
A7: 1st Term Academic Year 2023 - 2024
A9: Surname: Romero Given Name: Marlo MI:
A10: Employment Status: (Put X)
C11: Regular | J11: Contractual
C13: Probationary | J13: Part-Time
A14: TEACHING LOAD
A15: A. Basic Load/Built-In
A16: Subj Code | B16: Descriptive Title | D16: Day | E16: Time | F16: Room | G16: Section | H16: No. of Students | I16: Units | J16: Units | K16: Total | L16: Total
I17: (lec) | J17: (lab) | K17: Units | L17: Hours
E19: TOTAL NUMBER OF UNITS/HRS (BASIC) : | K19: =SUM(K18:K18) -> 0 | L19: =SUM(L18:L18) -> 0
A20: B. Other Academic-Related Functions
A21: Subj Code | B21: Descriptive Title | D21: Day | E21: Time | H21: No. of Students | I21: Units | J21: Units | K21: Total | L21: Total
I22: (lec) | J22: (lab) | K22: Units | L22: Hours
D24: TOTAL NUMBER OF UNITS/HRS (OTHER FUNCTIONS): | K24: =SUM(K23) -> 0 | L24: =SUM(L23) -> 0
A25: C. Consultation Hours
A26: Day | D26: Time | G26: Venue | K26: Number of hrs
D31: TOTAL NUMBER OF UNITS/HRS (CONSULTATION):
D32: SUB-TOTAL (A-C) | K32: =L19+L24+K31 -> 0
A33: D. Overload
A34: Subj Code | B34: Descriptive Title | D34: Day | E34: Time | F34: Room | G34: Section | H34: No. of Students | I34: Units | J34: Units | K34: Total | L34: Total
I35: (lec) | J35: (lab) | K35: Units | L35: Hours
A36: IT 121 | B36: Information Management 2 | D36: Sat | E36: 01:00 PM-04:00PM | F36: Lab2 | G36: BSIT 3C | H36: 40 | I36: 2 | J36: 1 | K36: 3 | L36: 5
D37: Mon | E37: 11:00 AM-01:00 PM | F37: 20
A38: IT 122 | B38: Integrative Programming & Technologies 2 | D38: Tue | E38: 09:00 AM-12:00PM | F38: Lab3 | G38: BSIT 3D | H38: 40 | I38: 2 | J38: 1 | K38: 3 | L38: 5
D39: Sat | E39: 07:00 AM-09:00 AM | F39: 20
D40: TOTAL NUMBER OF UNITS / HRS (OVERLOAD) | K40: 10 | L40: 10
D41: GRAND TOTAL NUMBER OF UNITS/HRS (A-D) | K41: =SUM(K19,K24,K40) -> 10 | L41: =(L19+L24+K31+L40) -> 10
A43: Prepared by: | H43: Noted:
A45: Mr. Gabriel E. Casiño | H45: Ms. Merilyn A.Tangon
A46: Department Head | H46: Vice President for Academic Affairs
D48: Hon. Atty. Nadya Emano-Elipe
D49: OIC - President

Sheet Ubalde M
A1: TCC-ADMN-Form 001
A2: TAGOLOAN COMMUNITY COLLEGE
A3: Baluarte, Tagoloan Misamis Oriental
A4: (08822)750-835
A5: Member: Association of Local Colleges & Universities (ALCU)
A6: Individual Faculty Load Sheet
A7: 1st Term Academic Year 2023 - 2024
A9: Surname: Ubalde Given Name: Mary Anne MI: D
A10: Employment Status: (Put X)
C11: Regular | J11: Contractual
C13: Probationary | J13: Part-Time
A14: TEACHING LOAD
A15: A. Basic Load/Built-In
A16: Subj Code | B16: Descriptive Title | D16: Day | E16: Time | F16: Room | G16: Section | H16: No. of Students | I16: Units | J16: Units | K16: Total | L16: Total
I17: (lec) | J17: (lab) | K17: Units | L17: Hours
E19: TOTAL NUMBER OF UNITS/HRS (BASIC) : | K19: =SUM(K18:K18) -> 0 | L19: =SUM(L18:L18) -> 0
A20: B. Other Academic-Related Functions
A21: Subj Code | B21: Descriptive Title | D21: Day | E21: Time | H21: No. of Students | I21: Units | J21: Units | K21: Total | L21: Total
I22: (lec) | J22: (lab) | K22: Units | L22: Hours
D24: TOTAL NUMBER OF UNITS/HRS (OTHER FUNCTIONS): | K24: =SUM(K23) -> 0 | L24: =SUM(L23) -> 0
A25: C. Consultation Hours
A26: Day | D26: Time | G26: Venue | K26: Number of hrs
D31: TOTAL NUMBER OF UNITS/HRS (CONSULTATION):
D32: SUB-TOTAL (A-C) | K32: =L19+L24+K31 -> 0
A33: D. Overload
A34: Subj Code | B34: Descriptive Title | D34: Day | E34: Time | F34: Room | G34: Section | H34: No. of Students | I34: Units | J34: Units | K34: Total | L34: Total
I35: (lec) | J35: (lab) | K35: Units | L35: Hours
A36: IT 121 | B36: Computer Application | D36: MW | E36: 06:30-08:30PM | F36: Lab2 | G36: BSET AT 2C | H36: 40 | I36: 4 | K36: 4 | L36: 4
A37: IT 122 | B37: Computer Application | D37: TTH | E37: 06:30-08:30PM | F37: Lab3 | G37: BSET ET 2A | H37: 40 | I37: 4 | K37: 4 | L37: 4
D38: TOTAL NUMBER OF UNITS / HRS (OVERLOAD) | K38: 8 | L38: 8
D39: GRAND TOTAL NUMBER OF UNITS/HRS (A-D) | K39: =SUM(K19,K24,K38) -> 8 | L39: =(L19+L24+K31+L38) -> 8
A41: Prepared by: | H41: Noted:
A43: Mr. Gabriel E. Casiño | H43: Ms. Merilyn A.Tangon
A44: Department Head | H44: Vice President for Academic Affairs
D46: Hon. Atty. Nadya Emano-Elipe
D47: OIC - President

Sheet Ranara L
A1: TCC-ADMN-Form 001
A2: TAGOLOAN COMMUNITY COLLEGE
A3: Baluarte, Tagoloan Misamis Oriental
A4: (08822)750-835
A5: Member: Association of Local Colleges & Universities (ALCU)
A6: Individual Faculty Load Sheet
A7: 1st Term Academic Year 2023 - 2024
A9: Surname: Ranara Given Name: Leilani MI:
A10: Employment Status: (Put X)
C11: Regular | J11: Contractual
C13: Probationary | J13: Part-Time
A14: TEACHING LOAD
A15: A. Basic Load/Built-In
A16: Subj Code | B16: Descriptive Title | D16: Day | E16: Time | F16: Room | G16: Section | H16: No. of Students | I16: Units | J16: Units | K16: Total | L16: Total
I17: (lec) | J17: (lab) | K17: Units | L17: Hours
E19: TOTAL NUMBER OF UNITS/HRS (BASIC) : | K19: =SUM(K18:K18) -> 0 | L19: =SUM(L18:L18) -> 0
A20: B. Other Academic-Related Functions
A21: Subj Code | B21: Descriptive Title | D21: Day | E21: Time | H21: No. of Students | I21: Units | J21: Units | K21: Total | L21: Total
I22: (lec) | J22: (lab) | K22: Units | L22: Hours
D24: TOTAL NUMBER OF UNITS/HRS (OTHER FUNCTIONS): | K24: =SUM(K23) -> 0 | L24: =SUM(L23) -> 0
A25: C. Consultation Hours
A26: Day | D26: Time | G26: Venue | K26: Number of hrs
D31: TOTAL NUMBER OF UNITS/HRS (CONSULTATION):
D32: SUB-TOTAL (A-C) | K32: =L19+L24+K31 -> 0
A33: D. Overload
A34: Subj Code | B34: Descriptive Title | D34: Day | E34: Time | F34: Room | G34: Section | H34: No. of Students | I34: Units | J34: Units | K34: Total | L34: Total
I35: (lec) | J35: (lab) | K35: Units | L35: Hours
A36: IT 103 | B36: Integrated Application Software | D36: Sun | E36: 01:00 PM-3:00 PM | F36: 20B | G36: BSIT 1E | H36: 40 | I36: 2 | J36: 1 | K36: 3 | L36: 5
D37: Sun | E37: 03:00 PM-07:00 PM | F37: Lab3
D38: TOTAL NUMBER OF UNITS / HRS (OVERLOAD) | K38: 6 | L38: 10
D39: GRAND TOTAL NUMBER OF UNITS/HRS (A-D) | K39: =SUM(K19,K24,K38) -> 6 | L39: =(L19+L24+K31+L38) -> 10
A41: Prepared by: | H41: Noted:
A43: Mr. Gabriel E. Casiño | H43: Ms. Merilyn A.Tangon
A44: Department Head | H44: Vice President for Academic Affairs
D46: Hon. Atty. Nadya Emano-Elipe
D47: OIC - President
